Error creating database tables: (psycopg2.OperationalError) connection to server at "localhost" (::1), port 5432 failed: Connection refused
	Is the server running on that host and accepting TCP/IP connections?
connection to server at "localhost" (127.0.0.1), port 5432 failed: Connection refused
	Is the server running on that host and accepting TCP/IP connections?

(Background on this error at: https://sqlalche.me/e/20/e3q8)
Traceback (most recent call last):
  File "/openhands/poetry/openhands-ai-5O4_aCHf-py3.12/lib/python3.12/site-packages/sqlalchemy/engine/base.py", line 145, in __init__
    self._dbapi_connection = engine.raw_connection()
                             ^^^^^^^^^^^^^^^^^^^^^^^
  File "/openhands/poetry/openhands-ai-5O4_aCHf-py3.12/lib/python3.12/site-packages/sqlalchemy/engine/base.py", line 3292, in raw_connection
    return self.pool.connect()
           ^^^^^^^^^^^^^^^^^^^
  File "/openhands/poetry/openhands-ai-5O4_aCHf-py3.12/lib/python3.12/site-packages/sqlalchemy/pool/base.py", line 452, in connect
    return _ConnectionFairy._checkout(self)
           ^^^^^^^^^^^^^^^^^^^^^^^^^^^^^^^^
  File "/openhands/poetry/openhands-ai-5O4_aCHf-py3.12/lib/python3.12/site-packages/sqlalchemy/pool/base.py", line 1269, in _checkout
    fairy = _ConnectionRecord.checkout(pool)
            ^^^^^^^^^^^^^^^^^^^^^^^^^^^^^^^^
  File "/openhands/poetry/openhands-ai-5O4_aCHf-py3.12/lib/python3.12/site-packages/sqlalchemy/pool/base.py", line 716, in checkout
    rec = pool._do_get()
          ^^^^^^^^^^^^^^
  File "/openhands/poetry/openhands-ai-5O4_aCHf-py3.12/lib/python3.12/site-packages/sqlalchemy/pool/impl.py", line 169, in _do_get
    with util.safe_reraise():
         ^^^^^^^^^^^^^^^^^^^
  File "/openhands/poetry/openhands-ai-5O4_aCHf-py3.12/lib/python3.12/site-packages/sqlalchemy/util/langhelpers.py", line 146, in __exit__
    raise exc_value.with_traceback(exc_tb)
  File "/openhands/poetry/openhands-ai-5O4_aCHf-py3.12/lib/python3.12/site-packages/sqlalchemy/pool/impl.py", line 167, in _do_get
    return self._create_connection()
           ^^^^^^^^^^^^^^^^^^^^^^^^^
  File "/openhands/poetry/openhands-ai-5O4_aCHf-py3.12/lib/python3.12/site-packages/sqlalchemy/pool/base.py", line 393, in _create_connection
    return _ConnectionRecord(self)
           ^^^^^^^^^^^^^^^^^^^^^^^
  File "/openhands/poetry/openhands-ai-5O4_aCHf-py3.12/lib/python3.12/site-packages/sqlalchemy/pool/base.py", line 678, in __init__
    self.__connect()
  File "/openhands/poetry/openhands-ai-5O4_aCHf-py3.12/lib/python3.12/site-packages/sqlalchemy/pool/base.py", line 902, in __connect
    with util.safe_reraise():
         ^^^^^^^^^^^^^^^^^^^
  File "/openhands/poetry/openhands-ai-5O4_aCHf-py3.12/lib/python3.12/site-packages/sqlalchemy/util/langhelpers.py", line 146, in __exit__
    raise exc_value.with_traceback(exc_tb)
  File "/openhands/poetry/openhands-ai-5O4_aCHf-py3.12/lib/python3.12/site-packages/sqlalchemy/pool/base.py", line 898, in __connect
    self.dbapi_connection = connection = pool._invoke_creator(self)
                                         ^^^^^^^^^^^^^^^^^^^^^^^^^^
  File "/openhands/poetry/openhands-ai-5O4_aCHf-py3.12/lib/python3.12/site-packages/sqlalchemy/engine/create.py", line 637, in connect
    return dialect.connect(*cargs, **cparams)
           ^^^^^^^^^^^^^^^^^^^^^^^^^^^^^^^^^^
  File "/openhands/poetry/openhands-ai-5O4_aCHf-py3.12/lib/python3.12/site-packages/sqlalchemy/engine/default.py", line 616, in connect
    return self.loaded_dbapi.connect(*cargs, **cparams)
           ^^^^^^^^^^^^^^^^^^^^^^^^^^^^^^^^^^^^^^^^^^^^
  File "/openhands/poetry/openhands-ai-5O4_aCHf-py3.12/lib/python3.12/site-packages/psycopg2/__init__.py", line 122, in connect
    conn = _connect(dsn, connection_factory=connection_factory, **kwasync)
           ^^^^^^^^^^^^^^^^^^^^^^^^^^^^^^^^^^^^^^^^^^^^^^^^^^^^^^^^^^^^^^^
psycopg2.OperationalError: connection to server at "localhost" (::1), port 5432 failed: Connection refused
	Is the server running on that host and accepting TCP/IP connections?
connection to server at "localhost" (127.0.0.1), port 5432 failed: Connection refused
	Is the server running on that host and accepting TCP/IP connections?


The above exception was the direct cause of the following exception:

Traceback (most recent call last):
  File "/workspace/multiplayer-rock-paper-scissors-dev/src/app.py", line 23, in <module>
    db.create_all()
  File "/openhands/poetry/openhands-ai-5O4_aCHf-py3.12/lib/python3.12/site-packages/flask_sqlalchemy/extension.py", line 900, in create_all
    self._call_for_binds(bind_key, "create_all")
  File "/openhands/poetry/openhands-ai-5O4_aCHf-py3.12/lib/python3.12/site-packages/flask_sqlalchemy/extension.py", line 881, in _call_for_binds
    getattr(metadata, op_name)(bind=engine)
  File "/openhands/poetry/openhands-ai-5O4_aCHf-py3.12/lib/python3.12/site-packages/sqlalchemy/sql/schema.py", line 5828, in create_all
    bind._run_ddl_visitor(
  File "/openhands/poetry/openhands-ai-5O4_aCHf-py3.12/lib/python3.12/site-packages/sqlalchemy/engine/base.py", line 3242, in _run_ddl_visitor
    with self.begin() as conn:
         ^^^^^^^^^^^^
  File "/openhands/micromamba/envs/openhands/lib/python3.12/contextlib.py", line 137, in __enter__
    return next(self.gen)
           ^^^^^^^^^^^^^^
  File "/openhands/poetry/openhands-ai-5O4_aCHf-py3.12/lib/python3.12/site-packages/sqlalchemy/engine/base.py", line 3232, in begin
    with self.connect() as conn:
         ^^^^^^^^^^^^^^
  File "/openhands/poetry/openhands-ai-5O4_aCHf-py3.12/lib/python3.12/site-packages/sqlalchemy/engine/base.py", line 3268, in connect
    return self._connection_cls(self)
           ^^^^^^^^^^^^^^^^^^^^^^^^^^
  File "/openhands/poetry/openhands-ai-5O4_aCHf-py3.12/lib/python3.12/site-packages/sqlalchemy/engine/base.py", line 147, in __init__
    Connection._handle_dbapi_exception_noconnection(
  File "/openhands/poetry/openhands-ai-5O4_aCHf-py3.12/lib/python3.12/site-packages/sqlalchemy/engine/base.py", line 2430, in _handle_dbapi_exception_noconnection
    raise sqlalchemy_exception.with_traceback(exc_info[2]) from e
  File "/openhands/poetry/openhands-ai-5O4_aCHf-py3.12/lib/python3.12/site-packages/sqlalchemy/engine/base.py", line 145, in __init__
    self._dbapi_connection = engine.raw_connection()
                             ^^^^^^^^^^^^^^^^^^^^^^^
  File "/openhands/poetry/openhands-ai-5O4_aCHf-py3.12/lib/python3.12/site-packages/sqlalchemy/engine/base.py", line 3292, in raw_connection
    return self.pool.connect()
           ^^^^^^^^^^^^^^^^^^^
  File "/openhands/poetry/openhands-ai-5O4_aCHf-py3.12/lib/python3.12/site-packages/sqlalchemy/pool/base.py", line 452, in connect
    return _ConnectionFairy._checkout(self)
           ^^^^^^^^^^^^^^^^^^^^^^^^^^^^^^^^
  File "/openhands/poetry/openhands-ai-5O4_aCHf-py3.12/lib/python3.12/site-packages/sqlalchemy/pool/base.py", line 1269, in _checkout
    fairy = _ConnectionRecord.checkout(pool)
            ^^^^^^^^^^^^^^^^^^^^^^^^^^^^^^^^
  File "/openhands/poetry/openhands-ai-5O4_aCHf-py3.12/lib/python3.12/site-packages/sqlalchemy/pool/base.py", line 716, in checkout
    rec = pool._do_get()
          ^^^^^^^^^^^^^^
  File "/openhands/poetry/openhands-ai-5O4_aCHf-py3.12/lib/python3.12/site-packages/sqlalchemy/pool/impl.py", line 169, in _do_get
    with util.safe_reraise():
         ^^^^^^^^^^^^^^^^^^^
  File "/openhands/poetry/openhands-ai-5O4_aCHf-py3.12/lib/python3.12/site-packages/sqlalchemy/util/langhelpers.py", line 146, in __exit__
    raise exc_value.with_traceback(exc_tb)
  File "/openhands/poetry/openhands-ai-5O4_aCHf-py3.12/lib/python3.12/site-packages/sqlalchemy/pool/impl.py", line 167, in _do_get
    return self._create_connection()
           ^^^^^^^^^^^^^^^^^^^^^^^^^
  File "/openhands/poetry/openhands-ai-5O4_aCHf-py3.12/lib/python3.12/site-packages/sqlalchemy/pool/base.py", line 393, in _create_connection
    return _ConnectionRecord(self)
           ^^^^^^^^^^^^^^^^^^^^^^^
  File "/openhands/poetry/openhands-ai-5O4_aCHf-py3.12/lib/python3.12/site-packages/sqlalchemy/pool/base.py", line 678, in __init__
    self.__connect()
  File "/openhands/poetry/openhands-ai-5O4_aCHf-py3.12/lib/python3.12/site-packages/sqlalchemy/pool/base.py", line 902, in __connect
    with util.safe_reraise():
         ^^^^^^^^^^^^^^^^^^^
  File "/openhands/poetry/openhands-ai-5O4_aCHf-py3.12/lib/python3.12/site-packages/sqlalchemy/util/langhelpers.py", line 146, in __exit__
    raise exc_value.with_traceback(exc_tb)
  File "/openhands/poetry/openhands-ai-5O4_aCHf-py3.12/lib/python3.12/site-packages/sqlalchemy/pool/base.py", line 898, in __connect
    self.dbapi_connection = connection = pool._invoke_creator(self)
                                         ^^^^^^^^^^^^^^^^^^^^^^^^^^
  File "/openhands/poetry/openhands-ai-5O4_aCHf-py3.12/lib/python3.12/site-packages/sqlalchemy/engine/create.py", line 637, in connect
    return dialect.connect(*cargs, **cparams)
           ^^^^^^^^^^^^^^^^^^^^^^^^^^^^^^^^^^
  File "/openhands/poetry/openhands-ai-5O4_aCHf-py3.12/lib/python3.12/site-packages/sqlalchemy/engine/default.py", line 616, in connect
    return self.loaded_dbapi.connect(*cargs, **cparams)
           ^^^^^^^^^^^^^^^^^^^^^^^^^^^^^^^^^^^^^^^^^^^^
  File "/openhands/poetry/openhands-ai-5O4_aCHf-py3.12/lib/python3.12/site-packages/psycopg2/__init__.py", line 122, in connect
    conn = _connect(dsn, connection_factory=connection_factory, **kwasync)
           ^^^^^^^^^^^^^^^^^^^^^^^^^^^^^^^^^^^^^^^^^^^^^^^^^^^^^^^^^^^^^^^
sqlalchemy.exc.OperationalError: (psycopg2.OperationalError) connection to server at "localhost" (::1), port 5432 failed: Connection refused
	Is the server running on that host and accepting TCP/IP connections?
connection to server at "localhost" (127.0.0.1), port 5432 failed: Connection refused
	Is the server running on that host and accepting TCP/IP connections?

(Background on this error at: https://sqlalche.me/e/20/e3q8)

During handling of the above exception, another exception occurred:

Traceback (most recent call last):
  File "/openhands/poetry/openhands-ai-5O4_aCHf-py3.12/lib/python3.12/site-packages/sqlalchemy/engine/base.py", line 145, in __init__
    self._dbapi_connection = engine.raw_connection()
                             ^^^^^^^^^^^^^^^^^^^^^^^
  File "/openhands/poetry/openhands-ai-5O4_aCHf-py3.12/lib/python3.12/site-packages/sqlalchemy/engine/base.py", line 3292, in raw_connection
    return self.pool.connect()
           ^^^^^^^^^^^^^^^^^^^
  File "/openhands/poetry/openhands-ai-5O4_aCHf-py3.12/lib/python3.12/site-packages/sqlalchemy/pool/base.py", line 452, in connect
    return _ConnectionFairy._checkout(self)
           ^^^^^^^^^^^^^^^^^^^^^^^^^^^^^^^^
  File "/openhands/poetry/openhands-ai-5O4_aCHf-py3.12/lib/python3.12/site-packages/sqlalchemy/pool/base.py", line 1269, in _checkout
    fairy = _ConnectionRecord.checkout(pool)
            ^^^^^^^^^^^^^^^^^^^^^^^^^^^^^^^^
  File "/openhands/poetry/openhands-ai-5O4_aCHf-py3.12/lib/python3.12/site-packages/sqlalchemy/pool/base.py", line 716, in checkout
    rec = pool._do_get()
          ^^^^^^^^^^^^^^
  File "/openhands/poetry/openhands-ai-5O4_aCHf-py3.12/lib/python3.12/site-packages/sqlalchemy/pool/impl.py", line 169, in _do_get
    with util.safe_reraise():
         ^^^^^^^^^^^^^^^^^^^
  File "/openhands/poetry/openhands-ai-5O4_aCHf-py3.12/lib/python3.12/site-packages/sqlalchemy/util/langhelpers.py", line 146, in __exit__
    raise exc_value.with_traceback(exc_tb)
  File "/openhands/poetry/openhands-ai-5O4_aCHf-py3.12/lib/python3.12/site-packages/sqlalchemy/pool/impl.py", line 167, in _do_get
    return self._create_connection()
           ^^^^^^^^^^^^^^^^^^^^^^^^^
  File "/openhands/poetry/openhands-ai-5O4_aCHf-py3.12/lib/python3.12/site-packages/sqlalchemy/pool/base.py", line 393, in _create_connection
    return _ConnectionRecord(self)
           ^^^^^^^^^^^^^^^^^^^^^^^
  File "/openhands/poetry/openhands-ai-5O4_aCHf-py3.12/lib/python3.12/site-packages/sqlalchemy/pool/base.py", line 678, in __init__
    self.__connect()
  File "/openhands/poetry/openhands-ai-5O4_aCHf-py3.12/lib/python3.12/site-packages/sqlalchemy/pool/base.py", line 902, in __connect
    with util.safe_reraise():
         ^^^^^^^^^^^^^^^^^^^
  File "/openhands/poetry/openhands-ai-5O4_aCHf-py3.12/lib/python3.12/site-packages/sqlalchemy/util/langhelpers.py", line 146, in __exit__
    raise exc_value.with_traceback(exc_tb)
  File "/openhands/poetry/openhands-ai-5O4_aCHf-py3.12/lib/python3.12/site-packages/sqlalchemy/pool/base.py", line 898, in __connect
    self.dbapi_connection = connection = pool._invoke_creator(self)
                                         ^^^^^^^^^^^^^^^^^^^^^^^^^^
  File "/openhands/poetry/openhands-ai-5O4_aCHf-py3.12/lib/python3.12/site-packages/sqlalchemy/engine/create.py", line 637, in connect
    return dialect.connect(*cargs, **cparams)
           ^^^^^^^^^^^^^^^^^^^^^^^^^^^^^^^^^^
  File "/openhands/poetry/openhands-ai-5O4_aCHf-py3.12/lib/python3.12/site-packages/sqlalchemy/engine/default.py", line 616, in connect
    return self.loaded_dbapi.connect(*cargs, **cparams)
           ^^^^^^^^^^^^^^^^^^^^^^^^^^^^^^^^^^^^^^^^^^^^
  File "/openhands/poetry/openhands-ai-5O4_aCHf-py3.12/lib/python3.12/site-packages/psycopg2/__init__.py", line 122, in connect
    conn = _connect(dsn, connection_factory=connection_factory, **kwasync)
           ^^^^^^^^^^^^^^^^^^^^^^^^^^^^^^^^^^^^^^^^^^^^^^^^^^^^^^^^^^^^^^^
psycopg2.OperationalError: connection to server at "localhost" (::1), port 5432 failed: Connection refused
	Is the server running on that host and accepting TCP/IP connections?
connection to server at "localhost" (127.0.0.1), port 5432 failed: Connection refused
	Is the server running on that host and accepting TCP/IP connections?


The above exception was the direct cause of the following exception:

Traceback (most recent call last):
  File "<frozen runpy>", line 198, in _run_module_as_main
  File "<frozen runpy>", line 88, in _run_code
  File "/workspace/multiplayer-rock-paper-scissors-dev/src/app.py", line 29, in <module>
    db.create_all()
  File "/openhands/poetry/openhands-ai-5O4_aCHf-py3.12/lib/python3.12/site-packages/flask_sqlalchemy/extension.py", line 900, in create_all
    self._call_for_binds(bind_key, "create_all")
  File "/openhands/poetry/openhands-ai-5O4_aCHf-py3.12/lib/python3.12/site-packages/flask_sqlalchemy/extension.py", line 881, in _call_for_binds
    getattr(metadata, op_name)(bind=engine)
  File "/openhands/poetry/openhands-ai-5O4_aCHf-py3.12/lib/python3.12/site-packages/sqlalchemy/sql/schema.py", line 5828, in create_all
    bind._run_ddl_visitor(
  File "/openhands/poetry/openhands-ai-5O4_aCHf-py3.12/lib/python3.12/site-packages/sqlalchemy/engine/base.py", line 3242, in _run_ddl_visitor
    with self.begin() as conn:
         ^^^^^^^^^^^^
  File "/openhands/micromamba/envs/openhands/lib/python3.12/contextlib.py", line 137, in __enter__
    return next(self.gen)
           ^^^^^^^^^^^^^^
  File "/openhands/poetry/openhands-ai-5O4_aCHf-py3.12/lib/python3.12/site-packages/sqlalchemy/engine/base.py", line 3232, in begin
    with self.connect() as conn:
         ^^^^^^^^^^^^^^
  File "/openhands/poetry/openhands-ai-5O4_aCHf-py3.12/lib/python3.12/site-packages/sqlalchemy/engine/base.py", line 3268, in connect
    return self._connection_cls(self)
           ^^^^^^^^^^^^^^^^^^^^^^^^^^
  File "/openhands/poetry/openhands-ai-5O4_aCHf-py3.12/lib/python3.12/site-packages/sqlalchemy/engine/base.py", line 147, in __init__
    Connection._handle_dbapi_exception_noconnection(
  File "/openhands/poetry/openhands-ai-5O4_aCHf-py3.12/lib/python3.12/site-packages/sqlalchemy/engine/base.py", line 2430, in _handle_dbapi_exception_noconnection
    raise sqlalchemy_exception.with_traceback(exc_info[2]) from e
  File "/openhands/poetry/openhands-ai-5O4_aCHf-py3.12/lib/python3.12/site-packages/sqlalchemy/engine/base.py", line 145, in __init__
    self._dbapi_connection = engine.raw_connection()
                             ^^^^^^^^^^^^^^^^^^^^^^^
  File "/openhands/poetry/openhands-ai-5O4_aCHf-py3.12/lib/python3.12/site-packages/sqlalchemy/engine/base.py", line 3292, in raw_connection
    return self.pool.connect()
           ^^^^^^^^^^^^^^^^^^^
  File "/openhands/poetry/openhands-ai-5O4_aCHf-py3.12/lib/python3.12/site-packages/sqlalchemy/pool/base.py", line 452, in connect
    return _ConnectionFairy._checkout(self)
           ^^^^^^^^^^^^^^^^^^^^^^^^^^^^^^^^
  File "/openhands/poetry/openhands-ai-5O4_aCHf-py3.12/lib/python3.12/site-packages/sqlalchemy/pool/base.py", line 1269, in _checkout
    fairy = _ConnectionRecord.checkout(pool)
            ^^^^^^^^^^^^^^^^^^^^^^^^^^^^^^^^
  File "/openhands/poetry/openhands-ai-5O4_aCHf-py3.12/lib/python3.12/site-packages/sqlalchemy/pool/base.py", line 716, in checkout
    rec = pool._do_get()
          ^^^^^^^^^^^^^^
  File "/openhands/poetry/openhands-ai-5O4_aCHf-py3.12/lib/python3.12/site-packages/sqlalchemy/pool/impl.py", line 169, in _do_get
    with util.safe_reraise():
         ^^^^^^^^^^^^^^^^^^^
  File "/openhands/poetry/openhands-ai-5O4_aCHf-py3.12/lib/python3.12/site-packages/sqlalchemy/util/langhelpers.py", line 146, in __exit__
    raise exc_value.with_traceback(exc_tb)
  File "/openhands/poetry/openhands-ai-5O4_aCHf-py3.12/lib/python3.12/site-packages/sqlalchemy/pool/impl.py", line 167, in _do_get
    return self._create_connection()
           ^^^^^^^^^^^^^^^^^^^^^^^^^
  File "/openhands/poetry/openhands-ai-5O4_aCHf-py3.12/lib/python3.12/site-packages/sqlalchemy/pool/base.py", line 393, in _create_connection
    return _ConnectionRecord(self)
           ^^^^^^^^^^^^^^^^^^^^^^^
  File "/openhands/poetry/openhands-ai-5O4_aCHf-py3.12/lib/python3.12/site-packages/sqlalchemy/pool/base.py", line 678, in __init__
    self.__connect()
  File "/openhands/poetry/openhands-ai-5O4_aCHf-py3.12/lib/python3.12/site-packages/sqlalchemy/pool/base.py", line 902, in __connect
    with util.safe_reraise():
         ^^^^^^^^^^^^^^^^^^^
  File "/openhands/poetry/openhands-ai-5O4_aCHf-py3.12/lib/python3.12/site-packages/sqlalchemy/util/langhelpers.py", line 146, in __exit__
    raise exc_value.with_traceback(exc_tb)
  File "/openhands/poetry/openhands-ai-5O4_aCHf-py3.12/lib/python3.12/site-packages/sqlalchemy/pool/base.py", line 898, in __connect
    self.dbapi_connection = connection = pool._invoke_creator(self)
                                         ^^^^^^^^^^^^^^^^^^^^^^^^^^
  File "/openhands/poetry/openhands-ai-5O4_aCHf-py3.12/lib/python3.12/site-packages/sqlalchemy/engine/create.py", line 637, in connect
    return dialect.connect(*cargs, **cparams)
           ^^^^^^^^^^^^^^^^^^^^^^^^^^^^^^^^^^
  File "/openhands/poetry/openhands-ai-5O4_aCHf-py3.12/lib/python3.12/site-packages/sqlalchemy/engine/default.py", line 616, in connect
    return self.loaded_dbapi.connect(*cargs, **cparams)
           ^^^^^^^^^^^^^^^^^^^^^^^^^^^^^^^^^^^^^^^^^^^^
  File "/openhands/poetry/openhands-ai-5O4_aCHf-py3.12/lib/python3.12/site-packages/psycopg2/__init__.py", line 122, in connect
    conn = _connect(dsn, connection_factory=connection_factory, **kwasync)
           ^^^^^^^^^^^^^^^^^^^^^^^^^^^^^^^^^^^^^^^^^^^^^^^^^^^^^^^^^^^^^^^
sqlalchemy.exc.OperationalError: (psycopg2.OperationalError) connection to server at "localhost" (::1), port 5432 failed: Connection refused
	Is the server running on that host and accepting TCP/IP connections?
connection to server at "localhost" (127.0.0.1), port 5432 failed: Connection refused
	Is the server running on that host and accepting TCP/IP connections?

(Background on this error at: https://sqlalche.me/e/20/e3q8)
